Workbook

Sheet Synthèse
A1: Forteresse Ø30 — bilan matériaux
A2: Calculé depuis l'onglet Détail. Les tourelles (60 Heavy, 30 Tek, 6 Tesla) sont déjà en inventaire : ne fabriquez que la colonne « À fabriquer ».
A4: Nombre de structures
A5: Poste | B5: Structures | C5: Devenir
A6: Structure des 8 plans | B6: =SUMIFS(Détail!$C$5:$C$29,Détail!$A$5:$A$29,A6) -> 4669 | C6: définitives
A7: Ancres temporaires (démolies) | B7: =SUMIFS(Détail!$C$5:$C$29,Détail!$A$5:$A$29,A7) -> 9 | C7: démolies à la fin
A8: Murs de pics | B8: =SUMIFS(Détail!$C$5:$C$29,Détail!$A$5:$A$29,A8) -> 74 | C8: définitifs, posés à la main
A9: Murs de chaume (démolis) | B9: =SUMIFS(Détail!$C$5:$C$29,Détail!$A$5:$A$29,A9) -> 96 | C9: démolis après la pose des tourelles
A10: Équipements | B10: =SUMIFS(Détail!$C$5:$C$29,Détail!$A$5:$A$29,A10) -> 45 | C10: définitifs, hors plans
A11: Tourelles (déjà en inventaire) | B11: =SUMIFS(Détail!$C$5:$C$29,Détail!$A$5:$A$29,A11) -> 96 | C11: définitives, déjà en inventaire
A12: Total à poser | B12: =SUM(B6:B11) -> 4989 | C12: =B12-B7-B9 -> 4884
A14: Matériaux par poste
A15: Poste | B15: Lingots de métal | C15: Pâte cimentée | D15: Électroniques | E15: Polymère | F15: Cristal | G15: Élément | H15: Perles noires | I15: Huile | J15: Poudre étincelante | K15: Cuir | L15: Fibre | M15: Chaume | N15: Bois
A16: Structure des 8 plans | B16: =SUMIFS(Détail!$R$5:$R$29,Détail!$A$5:$A$29,$A16) -> 108712 | C16: =SUMIFS(Détail!$S$5:$S$29,Détail!$A$5:$A$29,$A16) -> 31285 | D16: =SUMIFS(Détail!$T$5:$T$29,Détail!$A$5:$A$29,$A16) -> 0 | E16: =SUMIFS(Détail!$U$5:$U$29,Détail!$A$5:$A$29,$A16) -> 0 | F16: =SUMIFS(Détail!$V$5:$V$29,Détail!$A$5:$A$29,$A16) -> 0 | G16: =SUMIFS(Détail!$W$5:$W$29,Détail!$A$5:$A$29,$A16) -> 0 | H16: =SUMIFS(Détail!$X$5:$X$29,Détail!$A$5:$A$29,$A16) -> 0 | I16: =SUMIFS(Détail!$Y$5:$Y$29,Détail!$A$5:$A$29,$A16) -> 0 | J16: =SUMIFS(Détail!$Z$5:$Z$29,Détail!$A$5:$A$29,$A16) -> 0 | K16: =SUMIFS(Détail!$AA$5:$AA$29,Détail!$A$5:$A$29,$A16) -> 0 | L16: =SUMIFS(Détail!$AB$5:$AB$29,Détail!$A$5:$A$29,$A16) -> 0 | M16: =SUMIFS(Détail!$AC$5:$AC$29,Détail!$A$5:$A$29,$A16) -> 0 | N16: =SUMIFS(Détail!$AD$5:$AD$29,Détail!$A$5:$A$29,$A16) -> 0
A17: Ancres temporaires (démolies) | B17: =SUMIFS(Détail!$R$5:$R$29,Détail!$A$5:$A$29,$A17) -> 117 | C17: =SUMIFS(Détail!$S$5:$S$29,Détail!$A$5:$A$29,$A17) -> 36 | D17: =SUMIFS(Détail!$T$5:$T$29,Détail!$A$5:$A$29,$A17) -> 0 | E17: =SUMIFS(Détail!$U$5:$U$29,Détail!$A$5:$A$29,$A17) -> 0 | F17: =SUMIFS(Détail!$V$5:$V$29,Détail!$A$5:$A$29,$A17) -> 0 | G17: =SUMIFS(Détail!$W$5:$W$29,Détail!$A$5:$A$29,$A17) -> 0 | H17: =SUMIFS(Détail!$X$5:$X$29,Détail!$A$5:$A$29,$A17) -> 0 | I17: =SUMIFS(Détail!$Y$5:$Y$29,Détail!$A$5:$A$29,$A17) -> 0 | J17: =SUMIFS(Détail!$Z$5:$Z$29,Détail!$A$5:$A$29,$A17) -> 0 | K17: =SUMIFS(Détail!$AA$5:$AA$29,Détail!$A$5:$A$29,$A17) -> 0 | L17: =SUMIFS(Détail!$AB$5:$AB$29,Détail!$A$5:$A$29,$A17) -> 0 | M17: =SUMIFS(Détail!$AC$5:$AC$29,Détail!$A$5:$A$29,$A17) -> 0 | N17: =SUMIFS(Détail!$AD$5:$AD$29,Détail!$A$5:$A$29,$A17) -> 0
A18: Murs de pics | B18: =SUMIFS(Détail!$R$5:$R$29,Détail!$A$5:$A$29,$A18) -> 1850 | C18: =SUMIFS(Détail!$S$5:$S$29,Détail!$A$5:$A$29,$A18) -> 0 | D18: =SUMIFS(Détail!$T$5:$T$29,Détail!$A$5:$A$29,$A18) -> 0 | E18: =SUMIFS(Détail!$U$5:$U$29,Détail!$A$5:$A$29,$A18) -> 0 | F18: =SUMIFS(Détail!$V$5:$V$29,Détail!$A$5:$A$29,$A18) -> 0 | G18: =SUMIFS(Détail!$W$5:$W$29,Détail!$A$5:$A$29,$A18) -> 0 | H18: =SUMIFS(Détail!$X$5:$X$29,Détail!$A$5:$A$29,$A18) -> 0 | I18: =SUMIFS(Détail!$Y$5:$Y$29,Détail!$A$5:$A$29,$A18) -> 0 | J18: =SUMIFS(Détail!$Z$5:$Z$29,Détail!$A$5:$A$29,$A18) -> 0 | K18: =SUMIFS(Détail!$AA$5:$AA$29,Détail!$A$5:$A$29,$A18) -> 1480 | L18: =SUMIFS(Détail!$AB$5:$AB$29,Détail!$A$5:$A$29,$A18) -> 2220 | M18: =SUMIFS(Détail!$AC$5:$AC$29,Détail!$A$5:$A$29,$A18) -> 0 | N18: =SUMIFS(Détail!$AD$5:$AD$29,Détail!$A$5:$A$29,$A18) -> 0
A19: Murs de chaume (démolis) | B19: =SUMIFS(Détail!$R$5:$R$29,Détail!$A$5:$A$29,$A19) -> 0 | C19: =SUMIFS(Détail!$S$5:$S$29,Détail!$A$5:$A$29,$A19) -> 0 | D19: =SUMIFS(Détail!$T$5:$T$29,Détail!$A$5:$A$29,$A19) -> 0 | E19: =SUMIFS(Détail!$U$5:$U$29,Détail!$A$5:$A$29,$A19) -> 0 | F19: =SUMIFS(Détail!$V$5:$V$29,Détail!$A$5:$A$29,$A19) -> 0 | G19: =SUMIFS(Détail!$W$5:$W$29,Détail!$A$5:$A$29,$A19) -> 0 | H19: =SUMIFS(Détail!$X$5:$X$29,Détail!$A$5:$A$29,$A19) -> 0 | I19: =SUMIFS(Détail!$Y$5:$Y$29,Détail!$A$5:$A$29,$A19) -> 0 | J19: =SUMIFS(Détail!$Z$5:$Z$29,Détail!$A$5:$A$29,$A19) -> 0 | K19: =SUMIFS(Détail!$AA$5:$AA$29,Détail!$A$5:$A$29,$A19) -> 0 | L19: =SUMIFS(Détail!$AB$5:$AB$29,Détail!$A$5:$A$29,$A19) -> 384 | M19: =SUMIFS(Détail!$AC$5:$AC$29,Détail!$A$5:$A$29,$A19) -> 672 | N19: =SUMIFS(Détail!$AD$5:$AD$29,Détail!$A$5:$A$29,$A19) -> 384
A20: Équipements | B20: =SUMIFS(Détail!$R$5:$R$29,Détail!$A$5:$A$29,$A20) -> 26000 | C20: =SUMIFS(Détail!$S$5:$S$29,Détail!$A$5:$A$29,$A20) -> 2900 | D20: =SUMIFS(Détail!$T$5:$T$29,Détail!$A$5:$A$29,$A20) -> 220 | E20: =SUMIFS(Détail!$U$5:$U$29,Détail!$A$5:$A$29,$A20) -> 5850 | F20: =SUMIFS(Détail!$V$5:$V$29,Détail!$A$5:$A$29,$A20) -> 3350 | G20: =SUMIFS(Détail!$W$5:$W$29,Détail!$A$5:$A$29,$A20) -> 220 | H20: =SUMIFS(Détail!$X$5:$X$29,Détail!$A$5:$A$29,$A20) -> 470 | I20: =SUMIFS(Détail!$Y$5:$Y$29,Détail!$A$5:$A$29,$A20) -> 1400 | J20: =SUMIFS(Détail!$Z$5:$Z$29,Détail!$A$5:$A$29,$A20) -> 100 | K20: =SUMIFS(Détail!$AA$5:$AA$29,Détail!$A$5:$A$29,$A20) -> 0 | L20: =SUMIFS(Détail!$AB$5:$AB$29,Détail!$A$5:$A$29,$A20) -> 0 | M20: =SUMIFS(Détail!$AC$5:$AC$29,Détail!$A$5:$A$29,$A20) -> 0 | N20: =SUMIFS(Détail!$AD$5:$AD$29,Détail!$A$5:$A$29,$A20) -> 0
A21: Tourelles (déjà en inventaire) | B21: =SUMIFS(Détail!$R$5:$R$29,Détail!$A$5:$A$29,$A21) -> 38400 | C21: =SUMIFS(Détail!$S$5:$S$29,Détail!$A$5:$A$29,$A21) -> 13500 | D21: =SUMIFS(Détail!$T$5:$T$29,Détail!$A$5:$A$29,$A21) -> 19800 | E21: =SUMIFS(Détail!$U$5:$U$29,Détail!$A$5:$A$29,$A21) -> 7500 | F21: =SUMIFS(Détail!$V$5:$V$29,Détail!$A$5:$A$29,$A21) -> 1200 | G21: =SUMIFS(Détail!$W$5:$W$29,Détail!$A$5:$A$29,$A21) -> 90 | H21: =SUMIFS(Détail!$X$5:$X$29,Détail!$A$5:$A$29,$A21) -> 0 | I21: =SUMIFS(Détail!$Y$5:$Y$29,Détail!$A$5:$A$29,$A21) -> 0 | J21: =SUMIFS(Détail!$Z$5:$Z$29,Détail!$A$5:$A$29,$A21) -> 0 | K21: =SUMIFS(Détail!$AA$5:$AA$29,Détail!$A$5:$A$29,$A21) -> 0 | L21: =SUMIFS(Détail!$AB$5:$AB$29,Détail!$A$5:$A$29,$A21) -> 0 | M21: =SUMIFS(Détail!$AC$5:$AC$29,Détail!$A$5:$A$29,$A21) -> 0 | N21: =SUMIFS(Détail!$AD$5:$AD$29,Détail!$A$5:$A$29,$A21) -> 0
A22: À fabriquer (hors tourelles) | B22: =SUM(B16:B20) -> 136679 | C22: =SUM(C16:C20) -> 34221 | D22: =SUM(D16:D20) -> 220 | E22: =SUM(E16:E20) -> 5850 | F22: =SUM(F16:F20) -> 3350 | G22: =SUM(G16:G20) -> 220 | H22: =SUM(H16:H20) -> 470 | I22: =SUM(I16:I20) -> 1400 | ... N22: =SUM(N16:N20) -> 384
A23: Total avec les tourelles | B23: =SUM(B16:B21) -> 175079 | C23: =SUM(C16:C21) -> 47721 | D23: =SUM(D16:D21) -> 20020 | E23: =SUM(E16:E21) -> 13350 | F23: =SUM(F16:F21) -> 4550 | G23: =SUM(G16:G21) -> 310 | H23: =SUM(H16:H21) -> 470 | I23: =SUM(I16:I21) -> 1400 | ... N23: =SUM(N16:N21) -> 384
A25: Équivalent en ressources brutes
A26: Recette (hypothèse, à vérifier sur votre serveur)
A27: Minerai par lingot | B27: 2
A28: Perles de silice par électronique | B28: 3
A29: Lingot par électronique | B29: 1
A30: Obsidienne par polymère | B30: 2
A31: Pâte par polymère | B31: 2
A32: Chitine/kératine par pâte | B32: 4
A33: Pierre par pâte | B33: 8
A34: Silex par poudre étincelante | B34: 2
A35: Pierre par poudre étincelante | B35: 1
A37: Ressource brute | B37: Hors tourelles | C37: Avec les tourelles
A38: Lingots de métal au total (électroniques comprises) | B38: =(B22+$B$29*D22) -> 136899 | C38: =(B23+$B$29*D23) -> 195099
A39: Minerai de métal | B39: =$B$27*(B22+$B$29*D22) -> 273798 | C39: =$B$27*(B23+$B$29*D23) -> 390198
A40: Pâte cimentée au total (polymère compris) | B40: =(C22+$B$31*E22) -> 45921 | C40: =(C23+$B$31*E23) -> 74421
A41: Chitine ou kératine | B41: =$B$32*(C22+$B$31*E22) -> 183684 | C41: =$B$32*(C23+$B$31*E23) -> 297684
A42: Pierre | B42: =$B$33*(C22+$B$31*E22)+$B$35*J22 -> 367468 | C42: =$B$33*(C23+$B$31*E23)+$B$35*J23 -> 595468
A43: Obsidienne | B43: =$B$30*E22 -> 11700 | C43: =$B$30*E23 -> 26700
A44: Perles de silice | B44: =$B$28*D22 -> 660 | C44: =$B$28*D23 -> 60060
...

Sheet Détail
A1: Bilan matériaux — détail par pièce
A2: Bleu = donnée saisie (nombre de pièces, coût unitaire) : modifiez-la, tout se recalcule. Noir = formule. Coûts unitaires : module 07 §6 et README §9 ; « oui » en colonne Estimation = coût non trouvé dans les sources.
A4: Poste | B4: Pièce | C4: Nombre | D4: Estimation | E4: Lingots de métal / u | F4: Pâte cimentée / u | G4: Électroniques / u | H4: Polymère / u | I4: Cristal / u | J4: Élément / u | K4: Perles noires / u | L4: Huile / u | M4: Poudre étincelante / u | N4: Cuir / u | O4: Fibre / u | P4: Chaume / u | Q4: Bois / u | R4: Lingots de métal total | S4: Pâte cimentée total | T4: Électroniques total | U4: Polymère total | V4: Cristal total | W4: Élément total | X4: Perles noires total | Y4: Huile total | Z4: Poudre étincelante total | AA4: Cuir total | AB4: Fibre total | AC4: Chaume total | AD4: Bois total
A5: Structure des 8 plans | B5: Mur métal | C5: 1076 | E5: 25 | F5: 7 | G5: 0 | H5: 0 | I5: 0 | J5: 0 | K5: 0 | L5: 0 | M5: 0 | N5: 0 | O5: 0 | P5: 0 | Q5: 0 | R5: =$C5*E5 -> 26900 | S5: =$C5*F5 -> 7532 | T5: =$C5*G5 -> 0 | U5: =$C5*H5 -> 0 | V5: =$C5*I5 -> 0 | W5: =$C5*J5 -> 0 | X5: =$C5*K5 -> 0 | Y5: =$C5*L5 -> 0 | ... AD5: =$C5*Q5 -> 0
A6: Structure des 8 plans | B6: Rampe inclinée métal (Sloped Railing) | C6: 892 | D6: oui | E6: 12 | F6: 3 | G6: 0 | H6: 0 | I6: 0 | J6: 0 | K6: 0 | L6: 0 | M6: 0 | N6: 0 | O6: 0 | P6: 0 | Q6: 0 | R6: =$C6*E6 -> 10704 | S6: =$C6*F6 -> 2676 | T6: =$C6*G6 -> 0 | U6: =$C6*H6 -> 0 | V6: =$C6*I6 -> 0 | W6: =$C6*J6 -> 0 | X6: =$C6*K6 -> 0 | Y6: =$C6*L6 -> 0 | ... AD6: =$C6*Q6 -> 0
A7: Structure des 8 plans | B7: Fondation triangle métal | C7: 684 | E7: 25 | F7: 8 | G7: 0 | H7: 0 | I7: 0 | J7: 0 | K7: 0 | L7: 0 | M7: 0 | N7: 0 | O7: 0 | P7: 0 | Q7: 0 | R7: =$C7*E7 -> 17100 | S7: =$C7*F7 -> 5472 | T7: =$C7*G7 -> 0 | U7: =$C7*H7 -> 0 | V7: =$C7*I7 -> 0 | W7: =$C7*J7 -> 0 | X7: =$C7*K7 -> 0 | Y7: =$C7*L7 -> 0 | ... AD7: =$C7*Q7 -> 0
A8: Structure des 8 plans | B8: Plafond triangle métal | C8: 629 | D8: oui | E8: 18 | F8: 5 | G8: 0 | H8: 0 | I8: 0 | J8: 0 | K8: 0 | L8: 0 | M8: 0 | N8: 0 | O8: 0 | P8: 0 | Q8: 0 | R8: =$C8*E8 -> 11322 | S8: =$C8*F8 -> 3145 | T8: =$C8*G8 -> 0 | U8: =$C8*H8 -> 0 | V8: =$C8*I8 -> 0 | W8: =$C8*J8 -> 0 | X8: =$C8*K8 -> 0 | Y8: =$C8*L8 -> 0 | ... AD8: =$C8*Q8 -> 0
A9: Structure des 8 plans | B9: Pilier métal | C9: 346 | E9: 25 | F9: 7 | G9: 0 | H9: 0 | I9: 0 | J9: 0 | K9: 0 | L9: 0 | M9: 0 | N9: 0 | O9: 0 | P9: 0 | Q9: 0 | R9: =$C9*E9 -> 8650 | S9: =$C9*F9 -> 2422 | T9: =$C9*G9 -> 0 | U9: =$C9*H9 -> 0 | V9: =$C9*I9 -> 0 | W9: =$C9*J9 -> 0 | X9: =$C9*K9 -> 0 | Y9: =$C9*L9 -> 0 | ... AD9: =$C9*Q9 -> 0
A10: Structure des 8 plans | B10: Fondation métal | C10: 344 | E10: 50 | F10: 15 | G10: 0 | H10: 0 | I10: 0 | J10: 0 | K10: 0 | L10: 0 | M10: 0 | N10: 0 | O10: 0 | P10: 0 | Q10: 0 | R10: =$C10*E10 -> 17200 | S10: =$C10*F10 -> 5160 | T10: =$C10*G10 -> 0 | U10: =$C10*H10 -> 0 | V10: =$C10*I10 -> 0 | W10: =$C10*J10 -> 0 | X10: =$C10*K10 -> 0 | Y10: =$C10*L10 -> 0 | ... AD10: =$C10*Q10 -> 0
A11: Structure des 8 plans | B11: Plafond métal | C11: 308 | E11: 35 | F11: 10 | G11: 0 | H11: 0 | I11: 0 | J11: 0 | K11: 0 | L11: 0 | M11: 0 | N11: 0 | O11: 0 | P11: 0 | Q11: 0 | R11: =$C11*E11 -> 10780 | S11: =$C11*F11 -> 3080 | T11: =$C11*G11 -> 0 | U11: =$C11*H11 -> 0 | V11: =$C11*I11 -> 0 | W11: =$C11*J11 -> 0 | X11: =$C11*K11 -> 0 | Y11: =$C11*L11 -> 0 | ... AD11: =$C11*Q11 -> 0
A12: Structure des 8 plans | B12: Pilier fin métal (Thin Pillar) | C12: 166 | D12: oui | E12: 13 | F12: 4 | G12: 0 | H12: 0 | I12: 0 | J12: 0 | K12: 0 | L12: 0 | M12: 0 | N12: 0 | O12: 0 | P12: 0 | Q12: 0 | R12: =$C12*E12 -> 2158 | S12: =$C12*F12 -> 664 | T12: =$C12*G12 -> 0 | U12: =$C12*H12 -> 0 | V12: =$C12*I12 -> 0 | W12: =$C12*J12 -> 0 | X12: =$C12*K12 -> 0 | Y12: =$C12*L12 -> 0 | ... AD12: =$C12*Q12 -> 0
A13: Structure des 8 plans | B13: Pilier fin couché métal (Flat Thin Pillar) | C13: 94 | D13: oui | E13: 13 | F13: 4 | G13: 0 | H13: 0 | I13: 0 | J13: 0 | K13: 0 | L13: 0 | M13: 0 | N13: 0 | O13: 0 | P13: 0 | Q13: 0 | R13: =$C13*E13 -> 1222 | S13: =$C13*F13 -> 376 | T13: =$C13*G13 -> 0 | U13: =$C13*H13 -> 0 | V13: =$C13*I13 -> 0 | W13: =$C13*J13 -> 0 | X13: =$C13*K13 -> 0 | Y13: =$C13*L13 -> 0 | ... AD13: =$C13*Q13 -> 0
A14: Structure des 8 plans | B14: Cadre de porte double métal | C14: 76 | D14: oui | E14: 25 | F14: 7 | G14: 0 | H14: 0 | I14: 0 | J14: 0 | K14: 0 | L14: 0 | M14: 0 | N14: 0 | O14: 0 | P14: 0 | Q14: 0 | R14: =$C14*E14 -> 1900 | S14: =$C14*F14 -> 532 | T14: =$C14*G14 -> 0 | U14: =$C14*H14 -> 0 | V14: =$C14*I14 -> 0 | W14: =$C14*J14 -> 0 | X14: =$C14*K14 -> 0 | Y14: =$C14*L14 -> 0 | ... AD14: =$C14*Q14 -> 0
A15: Structure des 8 plans | B15: Demi-pilier fin métal (Half Thin Pillar) | C15: 43 | D15: oui | E15: 7 | F15: 2 | G15: 0 | H15: 0 | I15: 0 | J15: 0 | K15: 0 | L15: 0 | M15: 0 | N15: 0 | O15: 0 | P15: 0 | Q15: 0 | R15: =$C15*E15 -> 301 | S15: =$C15*F15 -> 86 | T15: =$C15*G15 -> 0 | U15: =$C15*H15 -> 0 | V15: =$C15*I15 -> 0 | W15: =$C15*J15 -> 0 | X15: =$C15*K15 -> 0 | Y15: =$C15*L15 -> 0 | ... AD15: =$C15*Q15 -> 0
A16: Structure des 8 plans | B16: Escalier métal | C16: 6 | D16: oui | E16: 50 | F16: 15 | G16: 0 | H16: 0 | I16: 0 | J16: 0 | K16: 0 | L16: 0 | M16: 0 | N16: 0 | O16: 0 | P16: 0 | Q16: 0 | R16: =$C16*E16 -> 300 | S16: =$C16*F16 -> 90 | T16: =$C16*G16 -> 0 | U16: =$C16*H16 -> 0 | V16: =$C16*I16 -> 0 | W16: =$C16*J16 -> 0 | X16: =$C16*K16 -> 0 | Y16: =$C16*L16 -> 0 | ... AD16: =$C16*Q16 -> 0
A17: Structure des 8 plans | B17: Plafond à trappe métal | C17: 5 | D17: oui | E17: 35 | F17: 10 | G17: 0 | H17: 0 | I17: 0 | J17: 0 | K17: 0 | L17: 0 | M17: 0 | N17: 0 | O17: 0 | P17: 0 | Q17: 0 | R17: =$C17*E17 -> 175 | S17: =$C17*F17 -> 50 | T17: =$C17*G17 -> 0 | U17: =$C17*H17 -> 0 | V17: =$C17*I17 -> 0 | W17: =$C17*J17 -> 0 | X17: =$C17*K17 -> 0 | Y17: =$C17*L17 -> 0 | ... AD17: =$C17*Q17 -> 0
A18: Ancres temporaires (démolies) | B18: Demi-pilier métal (ancre) | C18: 9 | D18: oui | E18: 13 | F18: 4 | G18: 0 | H18: 0 | I18: 0 | J18: 0 | K18: 0 | L18: 0 | M18: 0 | N18: 0 | O18: 0 | P18: 0 | Q18: 0 | R18: =$C18*E18 -> 117 | S18: =$C18*F18 -> 36 | T18: =$C18*G18 -> 0 | U18: =$C18*H18 -> 0 | V18: =$C18*I18 -> 0 | W18: =$C18*J18 -> 0 | X18: =$C18*K18 -> 0 | Y18: =$C18*L18 -> 0 | ... AD18: =$C18*Q18 -> 0
A19: Murs de pics | B19: Mur de pics métal | C19: 74 | E19: 25 | F19: 0 | G19: 0 | H19: 0 | I19: 0 | J19: 0 | K19: 0 | L19: 0 | M19: 0 | N19: 20 | O19: 30 | P19: 0 | Q19: 0 | R19: =$C19*E19 -> 1850 | S19: =$C19*F19 -> 0 | T19: =$C19*G19 -> 0 | U19: =$C19*H19 -> 0 | V19: =$C19*I19 -> 0 | W19: =$C19*J19 -> 0 | X19: =$C19*K19 -> 0 | Y19: =$C19*L19 -> 0 | ... AD19: =$C19*Q19 -> 0
A20: Murs de chaume (démolis) | B20: Mur de chaume (gabarit de pose, à démolir) | C20: 96 | D20: oui | E20: 0 | F20: 0 | G20: 0 | H20: 0 | I20: 0 | J20: 0 | K20: 0 | L20: 0 | M20: 0 | N20: 0 | O20: 4 | P20: 7 | Q20: 4 | R20: =$C20*E20 -> 0 | S20: =$C20*F20 -> 0 | T20: =$C20*G20 -> 0 | U20: =$C20*H20 -> 0 | V20: =$C20*I20 -> 0 | W20: =$C20*J20 -> 0 | X20: =$C20*K20 -> 0 | Y20: =$C20*L20 -> 0 | ... AD20: =$C20*Q20 -> 384
A21: Équipements | B21: Stockage dédié Tek (Tek Dedicated Storage) | C21: 20 | E21: 125 | F21: 0 | G21: 0 | H21: 55 | I21: 75 | J21: 3 | K21: 4 | L21: 0 | M21: 0 | N21: 0 | O21: 0 | P21: 0 | Q21: 0 | R21: =$C21*E21 -> 2500 | S21: =$C21*F21 -> 0 | T21: =$C21*G21 -> 0 | U21: =$C21*H21 -> 1100 | V21: =$C21*I21 -> 1500 | W21: =$C21*J21 -> 60 | X21: =$C21*K21 -> 80 | Y21: =$C21*L21 -> 0 | ... AD21: =$C21*Q21 -> 0
A22: Équipements | B22: Coffre-fort (Vault) | C22: 20 | D22: oui | E22: 500 | F22: 100 | G22: 0 | H22: 90 | I22: 0 | J22: 0 | K22: 0 | L22: 70 | M22: 0 | N22: 0 | O22: 0 | P22: 0 | Q22: 0 | R22: =$C22*E22 -> 10000 | S22: =$C22*F22 -> 2000 | T22: =$C22*G22 -> 0 | U22: =$C22*H22 -> 1800 | V22: =$C22*I22 -> 0 | W22: =$C22*J22 -> 0 | X22: =$C22*K22 -> 0 | Y22: =$C22*L22 -> 1400 | ... AD22: =$C22*Q22 -> 0
A23: Équipements | B23: Générateur Tek | C23: 2 | E23: 2400 | F23: 0 | G23: 0 | H23: 500 | I23: 250 | J23: 30 | K23: 120 | L23: 0 | M23: 0 | N23: 0 | O23: 0 | P23: 0 | Q23: 0 | R23: =$C23*E23 -> 4800 | S23: =$C23*F23 -> 0 | T23: =$C23*G23 -> 0 | U23: =$C23*H23 -> 1000 | V23: =$C23*I23 -> 500 | W23: =$C23*J23 -> 60 | X23: =$C23*K23 -> 240 | Y23: =$C23*L23 -> 0 | ... AD23: =$C23*Q23 -> 0
A24: Équipements | B24: Réplicateur Tek | C24: 1 | E24: 5000 | F24: 0 | G24: 0 | H24: 800 | I24: 600 | J24: 100 | K24: 150 | L24: 0 | M24: 0 | N24: 0 | O24: 0 | P24: 0 | Q24: 0 | R24: =$C24*E24 -> 5000 | S24: =$C24*F24 -> 0 | T24: =$C24*G24 -> 0 | U24: =$C24*H24 -> 800 | V24: =$C24*I24 -> 600 | W24: =$C24*J24 -> 100 | X24: =$C24*K24 -> 150 | Y24: =$C24*L24 -> 0 | ... AD24: =$C24*Q24 -> 0
A25: Équipements | B25: Forge à vapeur (Steam Forge) | C25: 1 | E25: 3250 | F25: 600 | G25: 200 | H25: 1000 | I25: 500 | J25: 0 | K25: 0 | L25: 0 | M25: 0 | N25: 0 | O25: 0 | P25: 0 | Q25: 0 | R25: =$C25*E25 -> 3250 | S25: =$C25*F25 -> 600 | T25: =$C25*G25 -> 200 | U25: =$C25*H25 -> 1000 | V25: =$C25*I25 -> 500 | W25: =$C25*J25 -> 0 | X25: =$C25*K25 -> 0 | Y25: =$C25*L25 -> 0 | ... AD25: =$C25*Q25 -> 0
A26: Équipements | B26: Labo de fortune (Makeshift Megalab) | C26: 1 | E26: 450 | F26: 300 | G26: 20 | H26: 150 | I26: 250 | J26: 0 | K26: 0 | L26: 0 | M26: 100 | N26: 0 | O26: 0 | P26: 0 | Q26: 0 | R26: =$C26*E26 -> 450 | S26: =$C26*F26 -> 300 | T26: =$C26*G26 -> 20 | U26: =$C26*H26 -> 150 | V26: =$C26*I26 -> 250 | W26: =$C26*J26 -> 0 | X26: =$C26*K26 -> 0 | Y26: =$C26*L26 -> 0 | ... AD26: =$C26*Q26 -> 0
A27: Tourelles (déjà en inventaire) | B27: Tourelle lourde (Heavy) | C27: 60 | E27: 540 | F27: 200 | G27: 270 | H27: 70 | I27: 0 | J27: 0 | K27: 0 | L27: 0 | M27: 0 | N27: 0 | O27: 0 | P27: 0 | Q27: 0 | R27: =$C27*E27 -> 32400 | S27: =$C27*F27 -> 12000 | T27: =$C27*G27 -> 16200 | U27: =$C27*H27 -> 4200 | V27: =$C27*I27 -> 0 | W27: =$C27*J27 -> 0 | X27: =$C27*K27 -> 0 | Y27: =$C27*L27 -> 0 | ... AD27: =$C27*Q27 -> 0
A28: Tourelles (déjà en inventaire) | B28: Tourelle Tek | C28: 30 | E28: 100 | F28: 50 | G28: 100 | H28: 50 | I28: 0 | J28: 3 | K28: 0 | L28: 0 | M28: 0 | N28: 0 | O28: 0 | P28: 0 | Q28: 0 | R28: =$C28*E28 -> 3000 | S28: =$C28*F28 -> 1500 | T28: =$C28*G28 -> 3000 | U28: =$C28*H28 -> 1500 | V28: =$C28*I28 -> 0 | W28: =$C28*J28 -> 90 | X28: =$C28*K28 -> 0 | Y28: =$C28*L28 -> 0 | ... AD28: =$C28*Q28 -> 0
A29: Tourelles (déjà en inventaire) | B29: Bobine Tesla | C29: 6 | E29: 500 | F29: 0 | G29: 100 | H29: 300 | I29: 200 | J29: 0 | K29: 0 | L29: 0 | M29: 0 | N29: 0 | O29: 0 | P29: 0 | Q29: 0 | R29: =$C29*E29 -> 3000 | S29: =$C29*F29 -> 0 | T29: =$C29*G29 -> 600 | U29: =$C29*H29 -> 1800 | V29: =$C29*I29 -> 1200 | W29: =$C29*J29 -> 0 | X29: =$C29*K29 -> 0 | Y29: =$C29*L29 -> 0 | ... AD29: =$C29*Q29 -> 0
A30: Total général (avec tourelles) | C30: =SUM(C5:C29) -> 4989 | R30: =SUM(R5:R29) -> 175079 | S30: =SUM(S5:S29) -> 47721 | T30: =SUM(T5:T29) -> 20020 | U30: =SUM(U5:U29) -> 13350 | V30: =SUM(V5:V29) -> 4550 | W30: =SUM(W5:W29) -> 310 | X30: =SUM(X5:X29) -> 470 | Y30: =SUM(Y5:Y29) -> 1400 | ... AD30: =SUM(AD5:AD29) -> 384

Sheet Par plan
A1: Structure par plan (hors tourelles et murs de chaume)
A2: Nombre de pièces par plan (bleu) ; coûts unitaires repris de l'onglet Détail (vert).
A4: Lingots / pièce | B4: =INDEX(Détail!$E$5:$E$29,MATCH("Mur métal",Détail!$B$5:$B$29,0)) -> 25 | C4: =INDEX(Détail!$E$5:$E$29,MATCH("Rampe inclinée métal (Sloped Railing)",Détail!$B$5:$B$29,0)) -> 12 | D4: =INDEX(Détail!$E$5:$E$29,MATCH("Fondation triangle métal",Détail!$B$5:$B$29,0)) -> 25 | E4: =INDEX(Détail!$E$5:$E$29,MATCH("Plafond triangle métal",Détail!$B$5:$B$29,0)) -> 18 | F4: =INDEX(Détail!$E$5:$E$29,MATCH("Pilier métal",Détail!$B$5:$B$29,0)) -> 25 | G4: =INDEX(Détail!$E$5:$E$29,MATCH("Fondation métal",Détail!$B$5:$B$29,0)) -> 50 | H4: =INDEX(Détail!$E$5:$E$29,MATCH("Plafond métal",Détail!$B$5:$B$29,0)) -> 35 | I4: =INDEX(Détail!$E$5:$E$29,MATCH("Pilier fin métal (Thin Pillar)",Détail!$B$5:$B$29,0)) -> 13 | J4: =INDEX(Détail!$E$5:$E$29,MATCH("Pilier fin couché métal (Flat Thin Pillar)",Détail!$B$5:$B$29,0)) -> 13 | K4: =INDEX(Détail!$E$5:$E$29,MATCH("Cadre de porte double métal",Détail!$B$5:$B$29,0)) -> 25 | L4: =INDEX(Détail!$E$5:$E$29,MATCH("Demi-pilier fin métal (Half Thin Pillar)",Détail!$B$5:$B$29,0)) -> 7 | M4: =INDEX(Détail!$E$5:$E$29,MATCH("Escalier métal",Détail!$B$5:$B$29,0)) -> 50 | N4: =INDEX(Détail!$E$5:$E$29,MATCH("Plafond à trappe métal",Détail!$B$5:$B$29,0)) -> 35
A5: Pâte / pièce | B5: =INDEX(Détail!$F$5:$F$29,MATCH("Mur métal",Détail!$B$5:$B$29,0)) -> 7 | C5: =INDEX(Détail!$F$5:$F$29,MATCH("Rampe inclinée métal (Sloped Railing)",Détail!$B$5:$B$29,0)) -> 3 | D5: =INDEX(Détail!$F$5:$F$29,MATCH("Fondation triangle métal",Détail!$B$5:$B$29,0)) -> 8 | E5: =INDEX(Détail!$F$5:$F$29,MATCH("Plafond triangle métal",Détail!$B$5:$B$29,0)) -> 5 | F5: =INDEX(Détail!$F$5:$F$29,MATCH("Pilier métal",Détail!$B$5:$B$29,0)) -> 7 | G5: =INDEX(Détail!$F$5:$F$29,MATCH("Fondation métal",Détail!$B$5:$B$29,0)) -> 15 | H5: =INDEX(Détail!$F$5:$F$29,MATCH("Plafond métal",Détail!$B$5:$B$29,0)) -> 10 | I5: =INDEX(Détail!$F$5:$F$29,MATCH("Pilier fin métal (Thin Pillar)",Détail!$B$5:$B$29,0)) -> 4 | J5: =INDEX(Détail!$F$5:$F$29,MATCH("Pilier fin couché métal (Flat Thin Pillar)",Détail!$B$5:$B$29,0)) -> 4 | K5: =INDEX(Détail!$F$5:$F$29,MATCH("Cadre de porte double métal",Détail!$B$5:$B$29,0)) -> 7 | L5: =INDEX(Détail!$F$5:$F$29,MATCH("Demi-pilier fin métal (Half Thin Pillar)",Détail!$B$5:$B$29,0)) -> 2 | M5: =INDEX(Détail!$F$5:$F$29,MATCH("Escalier métal",Détail!$B$5:$B$29,0)) -> 15 | N5: =INDEX(Détail!$F$5:$F$29,MATCH("Plafond à trappe métal",Détail!$B$5:$B$29,0)) -> 10
A6: Plan | B6: Mur métal | C6: Rampe inclinée métal (Sloped Railing) | D6: Fondation triangle métal | E6: Plafond triangle métal | F6: Pilier métal | G6: Fondation métal | H6: Plafond métal | I6: Pilier fin métal (Thin Pillar) | J6: Pilier fin couché métal (Flat Thin Pillar) | K6: Cadre de porte double métal | L6: Demi-pilier fin métal (Half Thin Pillar) | M6: Escalier métal | N6: Plafond à trappe métal | O6: Pièces | P6: Lingots | Q6: Pâte
A7: Plan 1 sol anneaux 12-15 | B7: 0 | C7: 0 | D7: 294 | E7: 0 | F7: 0 | G7: 147 | H7: 0 | I7: 0 | J7: 0 | K7: 0 | L7: 0 | M7: 0 | N7: 0 | O7: =SUM(B7:N7) -> 441 | P7: =SUMPRODUCT(B7:N7,B$4:N$4) -> 14700 | Q7: =SUMPRODUCT(B7:N7,B$5:N$5) -> 4557
A8: Plan 2 murs rampes tourelles anneaux 12-15 | B8: 319 | C8: 564 | D8: 0 | E8: 0 | F8: 226 | G8: 0 | H8: 0 | I8: 123 | J8: 94 | K8: 0 | L8: 43 | M8: 0 | N8: 0 | O8: =SUM(B8:N8) -> 1369 | P8: =SUMPRODUCT(B8:N8,B$4:N$4) -> 23515 | Q8: =SUMPRODUCT(B8:N8,B$5:N$5) -> 6461
A9: Plan 3 sol centre anneaux 0-11 | B9: 0 | C9: 0 | D9: 385 | E9: 0 | F9: 0 | G9: 192 | H9: 0 | I9: 0 | J9: 0 | K9: 0 | L9: 0 | M9: 0 | N9: 0 | O9: =SUM(B9:N9) -> 577 | P9: =SUMPRODUCT(B9:N9,B$4:N$4) -> 19225 | Q9: =SUMPRODUCT(B9:N9,B$5:N$5) -> 5960
A10: Plan 4 pod central | B10: 396 | C10: 0 | D10: 0 | E10: 170 | F10: 120 | G10: 0 | H10: 85 | I10: 0 | J10: 0 | K10: 17 | L10: 0 | M10: 6 | N10: 0 | O10: =SUM(B10:N10) -> 794 | P10: =SUMPRODUCT(B10:N10,B$4:N$4) -> 19660 | Q10: =SUMPRODUCT(B10:N10,B$5:N$5) -> 5521
A11: Plan 5 cage et casquette | B11: 361 | C11: 53 | D11: 0 | E11: 285 | F11: 0 | G11: 0 | H11: 136 | I11: 0 | J11: 0 | K11: 59 | L11: 0 | M11: 0 | N11: 5 | O11: =SUM(B11:N11) -> 899 | P11: =SUMPRODUCT(B11:N11,B$4:N$4) -> 21201 | Q11: =SUMPRODUCT(B11:N11,B$5:N$5) -> 5934
A12: Plan 6 toit rampes | B12: 0 | C12: 275 | D12: 0 | E12: 174 | F12: 0 | G12: 0 | H12: 87 | I12: 43 | J12: 0 | K12: 0 | L12: 0 | M12: 0 | N12: 0 | O12: =SUM(B12:N12) -> 579 | P12: =SUMPRODUCT(B12:N12,B$4:N$4) -> 10036 | Q12: =SUMPRODUCT(B12:N12,B$5:N$5) -> 2737
A13: Plan 7 tourelles cage L1 | B13: 0 | C13: 0 | D13: 0 | E13: 0 | F13: 0 | G13: 0 | H13: 0 | I13: 0 | J13: 0 | K13: 0 | L13: 0 | M13: 0 | N13: 0 | O13: =SUM(B13:N13) -> 0 | P13: =SUMPRODUCT(B13:N13,B$4:N$4) -> 0 | Q13: =SUMPRODUCT(B13:N13,B$5:N$5) -> 0
A14: Plan 8 plateforme future anneaux 9-11 | B14: 0 | C14: 0 | D14: 5 | E14: 0 | F14: 0 | G14: 5 | H14: 0 | I14: 0 | J14: 0 | K14: 0 | L14: 0 | M14: 0 | N14: 0 | O14: =SUM(B14:N14) -> 10 | P14: =SUMPRODUCT(B14:N14,B$4:N$4) -> 375 | Q14: =SUMPRODUCT(B14:N14,B$5:N$5) -> 115
A15: Total | B15: =SUM(B7:B14) -> 1076 | C15: =SUM(C7:C14) -> 892 | D15: =SUM(D7:D14) -> 684 | E15: =SUM(E7:E14) -> 629 | F15: =SUM(F7:F14) -> 346 | G15: =SUM(G7:G14) -> 344 | H15: =SUM(H7:H14) -> 308 | I15: =SUM(I7:I14) -> 166 | ... Q15: =SUM(Q7:Q14) -> 31285
A17: Le plan 2 contient en plus 36 murs de chaume + 30 Heavy + 6 Tesla, le plan 7 60 murs de chaume + 60 tourelles (onglet Détail).
